<?xml version='1.0' encoding='utf-8'?>
<mujoco>
    <compiler angle="radian" />
    <option integrator="implicitfast" timestep="0.002" />
    <default>
        <default class="omniwheel">
            <default class="omniplate" />
            <default class="omniroller">
                <geom condim="4" contype="1" conaffinity="0" friction="0.3 0.05 0.005" />
            </default>
        </default>
    </default>
    <worldbody>
        <body name="R_omni_plate" pos="0 0 0">
            <inertial pos="0 0 0" quat="0.707107 0 0 0.707107" mass="2.2423" diaginertia="0.0524193 0.0303095 0.0303095" />
            <joint name="R_omni_plate" pos="0 0 0" axis="0 1 0" />
            <geom size="0.11 0.0435" quat="0.707107 0.707107 0 0" type="cylinder" rgba="0.2 0.2 0.2 0.5" contype="0" conaffinity="0" />
            <body name="R_omni_roller0" pos="0.06064582562299426 0.0 0.016249999999999997">
                <inertial pos="0 0 0" quat="0.707107 0 0 0.707107" mass="0.1" diaginertia="0.03 0.03 0.03" />
                <joint name="R_omni_roller0" pos="0 0 0" axis="0.0 0.0 -1.0" />
                <geom type="sphere" size="0.065" class="omniroller" rgba="0.2 0.2 0.2 1" />
            </body>
            <body name="R_omni_roller1" pos="0.04439582562299427 0.0 0.04439582562299425">
                <inertial pos="0 0 0" quat="0.707107 0 0 0.707107" mass="0.1" diaginertia="0.03 0.03 0.03" />
                <joint name="R_omni_roller1" pos="0 0 0" axis="0.49999999999999994 0.0 -0.8660254037844387" />
                <geom type="sphere" size="0.065" class="omniroller" rgba="0.2 0.2 0.2 1" />
            </body>
            <body name="R_omni_roller2" pos="0.016250000000000007 0.0 0.060645825622994254">
                <inertial pos="0 0 0" quat="0.707107 0 0 0.707107" mass="0.1" diaginertia="0.03 0.03 0.03" />
                <joint name="R_omni_roller2" pos="0 0 0" axis="0.8660254037844386 0.0 -0.5000000000000001" />
                <geom type="sphere" size="0.065" class="omniroller" rgba="0.2 0.2 0.2 1" />
            </body>
            <body name="R_omni_roller3" pos="-0.01624999999999999 0.0 0.06064582562299426">
                <inertial pos="0 0 0" quat="0.707107 0 0 0.707107" mass="0.1" diaginertia="0.03 0.03 0.03" />
                <joint name="R_omni_roller3" pos="0 0 0" axis="1.0 0.0 -6.123233995736766e-17" />
                <geom type="sphere" size="0.065" class="omniroller" rgba="0.2 0.2 0.2 1" />
            </body>
            <body name="R_omni_roller4" pos="-0.044395825622994246 0.0 0.04439582562299427">
                <inertial pos="0 0 0" quat="0.707107 0 0 0.707107" mass="0.1" diaginertia="0.03 0.03 0.03" />
                <joint name="R_omni_roller4" pos="0 0 0" axis="0.8660254037844387 0.0 0.49999999999999983" />
                <geom type="sphere" size="0.065" class="omniroller" rgba="0.2 0.2 0.2 1" />
            </body>
            <body name="R_omni_roller5" pos="-0.060645825622994254 0.0 0.016250000000000014">
                <inertial pos="0 0 0" quat="0.707107 0 0 0.707107" mass="0.1" diaginertia="0.03 0.03 0.03" />
                <joint name="R_omni_roller5" pos="0 0 0" axis="0.5000000000000003 0.0 0.8660254037844385" />
                <geom type="sphere" size="0.065" class="omniroller" rgba="0.2 0.2 0.2 1" />
            </body>
            <body name="R_omni_roller6" pos="-0.06064582562299427 0.0 -0.01624999999999999">
                <inertial pos="0 0 0" quat="0.707107 0 0 0.707107" mass="0.1" diaginertia="0.03 0.03 0.03" />
                <joint name="R_omni_roller6" pos="0 0 0" axis="1.2246467991473532e-16 0.0 1.0" />
                <geom type="sphere" size="0.065" class="omniroller" rgba="0.2 0.2 0.2 1" />
            </body>
            <body name="R_omni_roller7" pos="-0.04439582562299428 0.0 -0.04439582562299424">
                <inertial pos="0 0 0" quat="0.707107 0 0 0.707107" mass="0.1" diaginertia="0.03 0.03 0.03" />
                <joint name="R_omni_roller7" pos="0 0 0" axis="-0.4999999999999998 0.0 0.8660254037844388" />
                <geom type="sphere" size="0.065" class="omniroller" rgba="0.2 0.2 0.2 1" />
            </body>
            <body name="R_omni_roller8" pos="-0.01625000000000002 0.0 -0.060645825622994254">
                <inertial pos="0 0 0" quat="0.707107 0 0 0.707107" mass="0.1" diaginertia="0.03 0.03 0.03" />
                <joint name="R_omni_roller8" pos="0 0 0" axis="-0.8660254037844384 0.0 0.5000000000000004" />
                <geom type="sphere" size="0.065" class="omniroller" rgba="0.2 0.2 0.2 1" />
            </body>
            <body name="R_omni_roller9" pos="0.016249999999999973 0.0 -0.06064582562299427">
                <inertial pos="0 0 0" quat="0.707107 0 0 0.707107" mass="0.1" diaginertia="0.03 0.03 0.03" />
                <joint name="R_omni_roller9" pos="0 0 0" axis="-1.0 0.0 1.8369701987210297e-16" />
                <geom type="sphere" size="0.065" class="omniroller" rgba="0.2 0.2 0.2 1" />
            </body>
            <body name="R_omni_roller10" pos="0.044395825622994226 0.0 -0.04439582562299428">
                <inertial pos="0 0 0" quat="0.707107 0 0 0.707107" mass="0.1" diaginertia="0.03 0.03 0.03" />
                <joint name="R_omni_roller10" pos="0 0 0" axis="-0.866025403784439 0.0 -0.49999999999999933" />
                <geom type="sphere" size="0.065" class="omniroller" rgba="0.2 0.2 0.2 1" />
            </body>
            <body name="R_omni_roller11" pos="0.060645825622994254 0.0 -0.01625000000000002">
                <inertial pos="0 0 0" quat="0.707107 0 0 0.707107" mass="0.1" diaginertia="0.03 0.03 0.03" />
                <joint name="R_omni_roller11" pos="0 0 0" axis="-0.5000000000000004 0.0 -0.8660254037844384" />
                <geom type="sphere" size="0.065" class="omniroller" rgba="0.2 0.2 0.2 1" />
            </body>
        </body>
    </worldbody>
</mujoco>