<mujoco model="DRBA_v1">
  <compiler angle="radian"/>
  <option gravity="0.85 0 -9.77"/>

  <visual>
    <global azimuth="-120" elevation="-20"/>
    <headlight ambient="0.3 0.3 0.3" diffuse="0.6 0.6 0.6" specular="0 0 0"/>
    <rgba haze="0.15 0.25 0.35 1"/>
  </visual>

  <asset>
    <mesh name="mobile_base" file="../meshes/mobile_base.STL"/>
    <mesh name="Left_motor" file="../meshes/Left_motor.STL"/>
    <mesh name="Right_motor" file="../meshes/Right_motor.STL"/>
    <mesh name="mobile_base2" file="../meshes/mobile_base2.STL"/>
    <mesh name="Left_motor2" file="../meshes/Left_motor2.STL"/>
    <mesh name="Right_motor2" file="../meshes/Right_motor2.STL"/>
    <mesh name="L_LinkOmni" file="../meshes/L_LinkOmni.STL"/>
    <mesh name="L_Omniwheel" file="../meshes/L_Omniwheel.STL"/>
    <mesh name="R_LinkOmni" file="../meshes/R_LinkOmni.STL"/>
    <mesh name="R_Omniwheel" file="../meshes/R_Omniwheel.STL"/>
    <mesh name="SitToStand" file="../meshes/SitToStand.STL"/>
    <mesh name="L_distal" file="../meshes/L_distal.STL"/>
    <mesh name="L_fore" file="../meshes/L_fore.STL"/>
    <mesh name="L_toInterface" file="../meshes/L_toInterface.STL"/>
    <mesh name="R_distal" file="../meshes/R_distal.STL"/>
    <mesh name="R_fore" file="../meshes/R_fore.STL"/>
    <mesh name="R_toInterface" file="../meshes/R_toInterface.STL"/>
    <mesh name="interface" file="../meshes/interface.STL"/>
    <mesh name="L_handle" file="../meshes/L_handle.STL"/>
    <mesh name="R_handle" file="../meshes/R_handle.STL"/>
    <texture name="texplane" type="2d" builtin="checker" rgb1=".2 .3 .4" rgb2=".1 0.15 0.2" width="100" height="100"/>
    <material name="MatPlane" reflectance="0.0" texture="texplane" texrepeat="1 1" texuniform="true"/>
  </asset>

  <default>
    <default class="DRBA">
      <default class="motor">
        <joint axis="0 1 0" damping="0.2"/>
        <motor ctrlrange="-1 1" gear="32" forcerange="-1000 1000"/>
      </default>
      <default class="distal_arm">
        <joint axis="0 0 1" damping="0.1" frictionloss="0.2"/>
      </default>
      <default class="fore_arm">
        <joint axis="0 0 1" damping="0.1" frictionloss="0.2"/>
      </default>
      <default class="ToInterface">
        <joint axis="0 0 1" damping="0.3" frictionloss="0.3"/>
      </default>
      <default class="visual_rob">
        <geom group="2" type="mesh" contype="0" conaffinity="0"/>
      </default>
      <default class="collision_rob">
        <geom group="3" type="mesh"/>
        <default class="rubber_wheel">
          <geom condim="6" friction="0.8 0.02 0.01" priority="1"/>
        </default>
      </default>
      <default class="omniwheel">
          <default class="omniplate" />
          <default class="omniroller">
              <geom condim="4" contype="1" conaffinity="0" friction="0.3 0.05 0.005" />
          </default>
      </default>
    </default>
  </default>


  <worldbody>
    <body name="floor" pos="0 0 -0.1601">
      <geom name="floor" type="plane" size="100 100 0.125" material="MatPlane" condim="3"/>
    </body>
    <body name="mobile_base" childclass="DRBA">
      <inertial pos="0.11688 0.021495 0.31592" quat="0.999934 -2.04321e-05 0.0114838 -0.000659424" mass="76.015" diaginertia="1.9924 1.6974 0.477811"/>
      <geom type="mesh" rgba="0.69804 0.69804 0.69804 1" mesh="mobile_base2" class="visual_rob"/>
  
      <body name="SitToStand" pos="0.1525 0 0.85592">
        <inertial pos="0.0124466 0.00409037 -0.113997" quat="0.999948 -0.000545667 -0.0102224 -1.39797e-05" mass="17.8756" diaginertia="0.137745 0.108967 0.064378"/>
        <geom type="mesh" rgba="0.698039 0.698039 0.698039 1" mesh="SitToStand" class="visual_rob"/>
        <body name="L_distal" pos="-0.001 0.149 -0.0797">
          <inertial pos="0.00251892 0.127057 0.00217991" quat="0.504914 0.495038 -0.504914 0.495038" mass="7.20006" diaginertia="0.00939901 0.00555303 0.00485103"/>
          <joint name="L_distal" pos="0 0 0" axis="0 0 1" class="distal_arm"/>
          <geom type="mesh" rgba="0.647059 0.619608 0.588235 1" mesh="L_distal" class="visual_rob"/>
          <body name="L_fore" pos="0.00494955 0.249951 0">
            <inertial pos="0.0994416 -0.0340428 0.00671173" quat="0.191065 0.674172 -0.187138 0.688452" mass="7.52382" diaginertia="0.021006 0.0179939 0.00764288"/>
            <joint name="L_fore" pos="0 0 0" axis="0 0 1" class="fore_arm"/>
            <geom type="mesh" rgba="0.6 0.6 0.6 1" mesh="L_fore" class="visual_rob"/>
            <body name="L_toInterface" pos="0.215084 -0.151451 0.011">
              <inertial pos="0.0130295 -0.0134398 -0.00377592" quat="0.687562 0.592604 -0.408848 -0.0944513" mass="0.561042" diaginertia="0.000443084 0.000355866 0.000288039"/>
              <joint name="L_toInterface" pos="0 0 0" axis="0 0 1" class="ToInterface"/>
              <geom type="mesh" rgba="0.866667 0.866667 0.890196 1" mesh="L_toInterface"/>
            </body>
          </body>
        </body>
        <body name="R_distal" pos="-0.001 -0.149 -0.0797">
          <inertial pos="0.00253462 -0.126949 0.00216323" quat="0.495116 0.504837 -0.495116 0.504837" mass="7.20347" diaginertia="0.00939914 0.00555315 0.00485108"/>
          <joint name="R_distal" pos="0 0 0" axis="0 0 -1" class="distal_arm"/>
          <geom type="mesh" rgba="0.647059 0.619608 0.588235 1" mesh="R_distal" class="visual_rob"/>
          <body name="R_fore" pos="0.00494955 -0.249951 0">
            <inertial pos="0.0994317 0.0340127 0.00670127" quat="-0.191065 0.674171 0.187138 0.688452" mass="7.52934" diaginertia="0.021006 0.0179943 0.00764335"/>
            <joint name="R_fore" pos="0 0 0" axis="0 0 -1" class="fore_arm"/>
            <geom type="mesh" rgba="0.776471 0.756863 0.737255 1" mesh="R_fore" class="visual_rob"/>
            <body name="R_toInterface" pos="0.215084 0.151451 0.011">
              <inertial pos="0.0130295 0.0134398 -0.00377114" quat="0.591766 0.687625 0.0925118 0.410397" mass="0.561042" diaginertia="0.000443708 0.000355244 0.000288036"/>
              <joint name="R_toInterface" pos="0 0 0" axis="0 0 -1" class="ToInterface"/>
              <geom type="mesh" rgba="0.866667 0.866667 0.890196 1" mesh="R_toInterface" class="visual_rob"/>
            </body>
          </body>
        </body>
      </body>
    </body>
    <!-- Interface -->
    <body name="interface" pos="-0.01754 0 0">
      <joint name="interface_tx" type="slide" axis="1 0 0" limited="false"/>
      <joint name="interface_ty" type="slide" axis="0 1 0" limited="false"/>
      <joint name="interface_tz" type="slide" axis="0 0 1" limited="false"/>
      <joint name="interface_rx" type="hinge" axis="1 0 0" limited="false"/>
      <joint name="interface_ry" type="hinge" axis="0 1 0" limited="false"/>
      <joint name="interface_rz" type="hinge" axis="0 0 1" limited="false"/>
      <!-- <inertial pos="0.43206 2.1793e-06 0.94217" quat="0.704633 0.704631 -0.0591028 0.0591098" mass="33.787" diaginertia="0.50785 0.39796 0.12113"/> -->
      <inertial pos="0.42917 1.3869e-05 0.80412" quat="0.706871 0.706872 -0.0182344 0.018275" mass="4.3133" diaginertia="0.075379 0.069746 0.0058555"/>
      <geom type="mesh" rgba="0.86667 0.86667 0.8902 1" mesh="interface" class="visual_rob"/>
      <body name="L_handle" pos="0.43797 0.25342 0.78622">
        <inertial pos="0.1026 -0.015165 0.0024098" quat="0.498254 0.485394 0.489071 0.526255" mass="3.5057" diaginertia="0.00834714 0.00760884 0.00349582"/>
        <!-- <joint name="L_handle" pos="0 0 0" axis="0 -1 0" type="slide"/> -->
        <geom type="mesh" rgba="0.75294 0.75294 0.75294 1" mesh="L_handle" class="visual_rob"/>
      </body>
      <body name="R_handle" pos="0.43797 -0.25342 0.78622">
        <inertial pos="0.10188 0.015045 0.0022443" quat="0.526246 0.489079 0.485375 0.498274" mass="3.5366" diaginertia="0.00834974 0.00760975 0.00349841"/>
        <!-- <joint name="R_handle" pos="0 0 0" axis="0 -1 0" type="slide"/> -->
        <geom type="mesh" rgba="0.65098 0.61961 0.58824 1" mesh="R_handle" class="visual_rob"/>
      </body>
    </body>
  </worldbody>
  <!-- Welding equality for closed-loop kinematics -->
  <equality>
    <weld body1="L_toInterface" body2="interface" torquescale="1000"/>
    <weld body1="R_toInterface" body2="interface" torquescale="1000"/>
  </equality>
</mujoco>
