<mujoco model="minicar">
  <compiler angle="radian" autolimits="true" inertiafromgeom="true"/>
  <option integrator="implicitfast" impratio="1" cone="elliptic" noslip_iterations="2">
    <flag multiccd="enable"/>
  </option>

  <default>
    <default class="stretch">
      <geom mass="0" solref="0.005 1"/>
      <general biastype="affine"/>
      <default class="wheel">
        <joint axis="0 0 1" damping=".3"/>
        <motor ctrlrange="-1 1" gear="16" forcerange="-100 100"/>
      </default>
      <default class="visual">
        <geom group="2" type="mesh" contype="0" conaffinity="0"/>
      </default>
      <default class="collision">
        <geom group="3" type="mesh"/>
        <default class="caster">
          <geom type="sphere" size=".02" pos="-0.24 0 .02" condim="1" priority="1"/>
        </default>
        <default class="rubber">
          <geom condim="6" friction="0.8 0.02 0.01" priority="1"/>
        </default>
      </default>
    </default>
  </default>

  <asset>
    <material name="Caster_Rollers_Red" rgba="0.8 0.001381 0 1"/>
    <material name="Generic_Black" rgba="0.036889 0.036889 0.036889 1"/>
    <material name="Wheel_Rubber_Gray" rgba="0.418986 0.424087 0.429225 1"/>
    <material name="Pantone_Cool_Gray_4_U" rgba="0.473531 0.479320 0.485150 1"/>

    <mesh file="meshes/base_link_0.obj"/>
    <mesh file="meshes/base_link_5.obj"/>
    <mesh file="meshes/base_link_8.obj"/>
    <mesh name="base_link_collision" file="meshes/base_link_casterless.stl"/>
    <mesh file="meshes/link_mast.obj"/>
    <mesh file="meshes/link_right_wheel_0.obj"/>
    <mesh file="meshes/link_right_wheel_1.obj"/>
    <mesh file="meshes/link_left_wheel_0.obj"/>
    <mesh file="meshes/link_left_wheel_1.obj"/>

  </asset>

  
  <worldbody>
    <body name="base_link" pos="0.5 0.0 -0.16" euler = "0.0 0.0 3.1492653" childclass="stretch">
      <!-- <freejoint/> -->
      <joint name="mbase_tx" type="slide" axis="1 0 0" limited="false"/>
      <joint name="mbase_ty" type="slide" axis="0 1 0" limited="false"/>
      <joint name="mbase_tz" type="slide" axis="0 0 1" limited="false"/>
      <joint name="mbase_rx" type="hinge" axis="1 0 0" limited="false"/>
      <joint name="mbase_ry" type="hinge" axis="0 1 0" limited="false"/>
      <joint name="mbase_rz" type="hinge" axis="0 0 1" limited="false"/>
      <geom mesh="base_link_0" material="Caster_Rollers_Red" class="visual" mass = "45"/>
      <geom mesh="base_link_5" material="Generic_Black" class="visual"/>
      <geom mesh="base_link_8" material="Pantone_Cool_Gray_4_U" class="visual"/>
      <geom class="collision" mesh="base_link_collision" mass="15.0"/>
      <geom class="caster"/>
      <body name="link_mast" pos="0 0 0.0284" quat="1 1 0 0">
        <geom material="Generic_Black" mesh="link_mast" class="visual"/>
        <geom mesh="link_mast" class="visual" mass="1.8285"/>
      </body>
      <body name="link_right_wheel" pos="0 -0.17035 0.0508" quat="1 -1 0 0">
        <joint name="joint_right_wheel" class="wheel"/>
        <geom mesh="link_right_wheel_0" material="Wheel_Rubber_Gray" class="visual" mass="0.15"/>
        <geom mesh="link_right_wheel_1" material="Generic_Black" class="visual" mass="25"/>
        <geom class="collision" type="cylinder" size=".05 .0125" pos="0 0 0.0125"/>
      </body>
      <body name="link_left_wheel" pos="0 0.17035 0.0508" quat="1 -1 0 0">
        <joint name="joint_left_wheel" class="wheel"/>
        <geom mesh="link_left_wheel_0" material="Wheel_Rubber_Gray" class="visual" mass="0.15"/>
        <geom mesh="link_left_wheel_1" material="Generic_Black" class="visual" mass="25"/>
        <geom class="collision" type="cylinder" size=".05 .0125" pos="0 0 -0.0125"/>
      </body>
    </body>
  </worldbody>

  <contact>
    <exclude body1="link_left_wheel" body2="base_link"/>
    <exclude body1="link_right_wheel" body2="base_link"/>
  </contact>

  <tendon>
    <fixed name="forward">
      <joint joint="joint_left_wheel" coef=".5"/>
      <joint joint="joint_right_wheel" coef=".5"/>
    </fixed>
    <fixed name="turn">
      <joint joint="joint_left_wheel" coef="-.5"/>
      <joint joint="joint_right_wheel" coef=".5"/>
    </fixed>
  </tendon>

  <actuator>
    <motor name="forward" tendon="forward" class="wheel"/>
    <motor name="turn" tendon="turn" class="wheel"/>
  </actuator>
</mujoco>
